<?xml version="1.0" encoding="UTF-8"?>
<!-- Generated by org.testng.reporters.JUnitXMLReporter -->
<testsuite hostname="DESKTOP-CTRD12V" ignored="0" name="Default test" tests="6" failures="5" timestamp="24 Dec 2017 08:59:08 GMT" time="220.521" errors="0">
  <testcase name="userLogin" time="49.818" classname="DataDrivenFramework.DataDrivenLoginTest">
    <failure type="java.lang.AssertionError" message="expected [My account - My Store] but found [Login - My Store]">
      <![CDATA[java.lang.AssertionError: expected [My account - My Store] but found [Login - My Store]at org.testng.Assert.fail(Assert.java:96)at org.testng.Assert.failNotEquals(Assert.java:776)at org.testng.Assert.assertEqualsImpl(Assert.java:137)at org.testng.Assert.assertEquals(Assert.java:118)at org.testng.Assert.assertEquals(Assert.java:453)at org.testng.Assert.assertEquals(Assert.java:463)at DataDrivenFramework.DataDrivenLoginTest.userLogin(DataDrivenLoginTest.java:33)at sun.reflect.NativeMethodAccessorImpl.invoke0(Native Method)at sun.reflect.NativeMethodAccessorImpl.invoke(Unknown Source)at sun.reflect.DelegatingMethodAccessorImpl.invoke(Unknown Source)at java.lang.reflect.Method.invoke(Unknown Source)at org.testng.internal.MethodInvocationHelper.invokeMethod(MethodInvocationHelper.java:124)at org.testng.internal.Invoker.invokeMethod(Invoker.java:571)at org.testng.internal.Invoker.invokeTestMethod(Invoker.java:707)at org.testng.internal.Invoker.invokeTestMethods(Invoker.java:979)at org.testng.internal.TestMethodWorker.invokeTestMethods(TestMethodWorker.java:125)at org.testng.internal.TestMethodWorker.run(TestMethodWorker.java:109)at org.testng.TestRunner.privateRun(TestRunner.java:648)at org.testng.TestRunner.run(TestRunner.java:505)at org.testng.SuiteRunner.runTest(SuiteRunner.java:455)at org.testng.SuiteRunner.runSequentially(SuiteRunner.java:450)at org.testng.SuiteRunner.privateRun(SuiteRunner.java:415)at org.testng.SuiteRunner.run(SuiteRunner.java:364)at org.testng.SuiteRunnerWorker.runSuite(SuiteRunnerWorker.java:52)at org.testng.SuiteRunnerWorker.run(SuiteRunnerWorker.java:84)at org.testng.TestNG.runSuitesSequentially(TestNG.java:1187)at org.testng.TestNG.runSuitesLocally(TestNG.java:1116)at org.testng.TestNG.runSuites(TestNG.java:1028)at org.testng.TestNG.run(TestNG.java:996)at org.testng.remote.AbstractRemoteTestNG.run(AbstractRemoteTestNG.java:114)at org.testng.remote.RemoteTestNG.initAndRun(RemoteTestNG.java:251)at org.testng.remote.RemoteTestNG.main(RemoteTestNG.java:77)]]>
    </failure>
  </testcase> <!-- userLogin -->
  <testcase name="userLogin" time="31.845" classname="DataDrivenFramework.DataDrivenLoginTest">
    <failure type="java.lang.AssertionError" message="expected [My account - My Store] but found [Login - My Store]">
      <![CDATA[java.lang.AssertionError: expected [My account - My Store] but found [Login - My Store]at org.testng.Assert.fail(Assert.java:96)at org.testng.Assert.failNotEquals(Assert.java:776)at org.testng.Assert.assertEqualsImpl(Assert.java:137)at org.testng.Assert.assertEquals(Assert.java:118)at org.testng.Assert.assertEquals(Assert.java:453)at org.testng.Assert.assertEquals(Assert.java:463)at DataDrivenFramework.DataDrivenLoginTest.userLogin(DataDrivenLoginTest.java:33)at sun.reflect.NativeMethodAccessorImpl.invoke0(Native Method)at sun.reflect.NativeMethodAccessorImpl.invoke(Unknown Source)at sun.reflect.DelegatingMethodAccessorImpl.invoke(Unknown Source)at java.lang.reflect.Method.invoke(Unknown Source)at org.testng.internal.MethodInvocationHelper.invokeMethod(MethodInvocationHelper.java:124)at org.testng.internal.Invoker.invokeMethod(Invoker.java:571)at org.testng.internal.Invoker.invokeTestMethod(Invoker.java:707)at org.testng.internal.Invoker.invokeTestMethods(Invoker.java:979)at org.testng.internal.TestMethodWorker.invokeTestMethods(TestMethodWorker.java:125)at org.testng.internal.TestMethodWorker.run(TestMethodWorker.java:109)at org.testng.TestRunner.privateRun(TestRunner.java:648)at org.testng.TestRunner.run(TestRunner.java:505)at org.testng.SuiteRunner.runTest(SuiteRunner.java:455)at org.testng.SuiteRunner.runSequentially(SuiteRunner.java:450)at org.testng.SuiteRunner.privateRun(SuiteRunner.java:415)at org.testng.SuiteRunner.run(SuiteRunner.java:364)at org.testng.SuiteRunnerWorker.runSuite(SuiteRunnerWorker.java:52)at org.testng.SuiteRunnerWorker.run(SuiteRunnerWorker.java:84)at org.testng.TestNG.runSuitesSequentially(TestNG.java:1187)at org.testng.TestNG.runSuitesLocally(TestNG.java:1116)at org.testng.TestNG.runSuites(TestNG.java:1028)at org.testng.TestNG.run(TestNG.java:996)at org.testng.remote.AbstractRemoteTestNG.run(AbstractRemoteTestNG.java:114)at org.testng.remote.RemoteTestNG.initAndRun(RemoteTestNG.java:251)at org.testng.remote.RemoteTestNG.main(RemoteTestNG.java:77)]]>
    </failure>
  </testcase> <!-- userLogin -->
  <testcase name="userLogin" time="29.115" classname="DataDrivenFramework.DataDrivenLoginTest">
    <failure type="java.lang.AssertionError" message="expected [My account - My Store] but found [Login - My Store]">
      <![CDATA[java.lang.AssertionError: expected [My account - My Store] but found [Login - My Store]at org.testng.Assert.fail(Assert.java:96)at org.testng.Assert.failNotEquals(Assert.java:776)at org.testng.Assert.assertEqualsImpl(Assert.java:137)at org.testng.Assert.assertEquals(Assert.java:118)at org.testng.Assert.assertEquals(Assert.java:453)at org.testng.Assert.assertEquals(Assert.java:463)at DataDrivenFramework.DataDrivenLoginTest.userLogin(DataDrivenLoginTest.java:33)at sun.reflect.NativeMethodAccessorImpl.invoke0(Native Method)at sun.reflect.NativeMethodAccessorImpl.invoke(Unknown Source)at sun.reflect.DelegatingMethodAccessorImpl.invoke(Unknown Source)at java.lang.reflect.Method.invoke(Unknown Source)at org.testng.internal.MethodInvocationHelper.invokeMethod(MethodInvocationHelper.java:124)at org.testng.internal.Invoker.invokeMethod(Invoker.java:571)at org.testng.internal.Invoker.invokeTestMethod(Invoker.java:707)at org.testng.internal.Invoker.invokeTestMethods(Invoker.java:979)at org.testng.internal.TestMethodWorker.invokeTestMethods(TestMethodWorker.java:125)at org.testng.internal.TestMethodWorker.run(TestMethodWorker.java:109)at org.testng.TestRunner.privateRun(TestRunner.java:648)at org.testng.TestRunner.run(TestRunner.java:505)at org.testng.SuiteRunner.runTest(SuiteRunner.java:455)at org.testng.SuiteRunner.runSequentially(SuiteRunner.java:450)at org.testng.SuiteRunner.privateRun(SuiteRunner.java:415)at org.testng.SuiteRunner.run(SuiteRunner.java:364)at org.testng.SuiteRunnerWorker.runSuite(SuiteRunnerWorker.java:52)at org.testng.SuiteRunnerWorker.run(SuiteRunnerWorker.java:84)at org.testng.TestNG.runSuitesSequentially(TestNG.java:1187)at org.testng.TestNG.runSuitesLocally(TestNG.java:1116)at org.testng.TestNG.runSuites(TestNG.java:1028)at org.testng.TestNG.run(TestNG.java:996)at org.testng.remote.AbstractRemoteTestNG.run(AbstractRemoteTestNG.java:114)at org.testng.remote.RemoteTestNG.initAndRun(RemoteTestNG.java:251)at org.testng.remote.RemoteTestNG.main(RemoteTestNG.java:77)]]>
    </failure>
  </testcase> <!-- userLogin -->
  <testcase name="userLogin" time="45.926" classname="DataDrivenFramework.DataDrivenLoginTest">
    <failure type="java.lang.AssertionError" message="expected [My account - My Store] but found [Login - My Store]">
      <![CDATA[java.lang.AssertionError: expected [My account - My Store] but found [Login - My Store]at org.testng.Assert.fail(Assert.java:96)at org.testng.Assert.failNotEquals(Assert.java:776)at org.testng.Assert.assertEqualsImpl(Assert.java:137)at org.testng.Assert.assertEquals(Assert.java:118)at org.testng.Assert.assertEquals(Assert.java:453)at org.testng.Assert.assertEquals(Assert.java:463)at DataDrivenFramework.DataDrivenLoginTest.userLogin(DataDrivenLoginTest.java:33)at sun.reflect.NativeMethodAccessorImpl.invoke0(Native Method)at sun.reflect.NativeMethodAccessorImpl.invoke(Unknown Source)at sun.reflect.DelegatingMethodAccessorImpl.invoke(Unknown Source)at java.lang.reflect.Method.invoke(Unknown Source)at org.testng.internal.MethodInvocationHelper.invokeMethod(MethodInvocationHelper.java:124)at org.testng.internal.Invoker.invokeMethod(Invoker.java:571)at org.testng.internal.Invoker.invokeTestMethod(Invoker.java:707)at org.testng.internal.Invoker.invokeTestMethods(Invoker.java:979)at org.testng.internal.TestMethodWorker.invokeTestMethods(TestMethodWorker.java:125)at org.testng.internal.TestMethodWorker.run(TestMethodWorker.java:109)at org.testng.TestRunner.privateRun(TestRunner.java:648)at org.testng.TestRunner.run(TestRunner.java:505)at org.testng.SuiteRunner.runTest(SuiteRunner.java:455)at org.testng.SuiteRunner.runSequentially(SuiteRunner.java:450)at org.testng.SuiteRunner.privateRun(SuiteRunner.java:415)at org.testng.SuiteRunner.run(SuiteRunner.java:364)at org.testng.SuiteRunnerWorker.runSuite(SuiteRunnerWorker.java:52)at org.testng.SuiteRunnerWorker.run(SuiteRunnerWorker.java:84)at org.testng.TestNG.runSuitesSequentially(TestNG.java:1187)at org.testng.TestNG.runSuitesLocally(TestNG.java:1116)at org.testng.TestNG.runSuites(TestNG.java:1028)at org.testng.TestNG.run(TestNG.java:996)at org.testng.remote.AbstractRemoteTestNG.run(AbstractRemoteTestNG.java:114)at org.testng.remote.RemoteTestNG.initAndRun(RemoteTestNG.java:251)at org.testng.remote.RemoteTestNG.main(RemoteTestNG.java:77)]]>
    </failure>
  </testcase> <!-- userLogin -->
  <testcase name="userLogin" time="28.258" classname="DataDrivenFramework.DataDrivenLoginTest">
    <failure type="java.lang.AssertionError" message="expected [My account - My Store] but found [Login - My Store]">
      <![CDATA[java.lang.AssertionError: expected [My account - My Store] but found [Login - My Store]at org.testng.Assert.fail(Assert.java:96)at org.testng.Assert.failNotEquals(Assert.java:776)at org.testng.Assert.assertEqualsImpl(Assert.java:137)at org.testng.Assert.assertEquals(Assert.java:118)at org.testng.Assert.assertEquals(Assert.java:453)at org.testng.Assert.assertEquals(Assert.java:463)at DataDrivenFramework.DataDrivenLoginTest.userLogin(DataDrivenLoginTest.java:33)at sun.reflect.NativeMethodAccessorImpl.invoke0(Native Method)at sun.reflect.NativeMethodAccessorImpl.invoke(Unknown Source)at sun.reflect.DelegatingMethodAccessorImpl.invoke(Unknown Source)at java.lang.reflect.Method.invoke(Unknown Source)at org.testng.internal.MethodInvocationHelper.invokeMethod(MethodInvocationHelper.java:124)at org.testng.internal.Invoker.invokeMethod(Invoker.java:571)at org.testng.internal.Invoker.invokeTestMethod(Invoker.java:707)at org.testng.internal.Invoker.invokeTestMethods(Invoker.java:979)at org.testng.internal.TestMethodWorker.invokeTestMethods(TestMethodWorker.java:125)at org.testng.internal.TestMethodWorker.run(TestMethodWorker.java:109)at org.testng.TestRunner.privateRun(TestRunner.java:648)at org.testng.TestRunner.run(TestRunner.java:505)at org.testng.SuiteRunner.runTest(SuiteRunner.java:455)at org.testng.SuiteRunner.runSequentially(SuiteRunner.java:450)at org.testng.SuiteRunner.privateRun(SuiteRunner.java:415)at org.testng.SuiteRunner.run(SuiteRunner.java:364)at org.testng.SuiteRunnerWorker.runSuite(SuiteRunnerWorker.java:52)at org.testng.SuiteRunnerWorker.run(SuiteRunnerWorker.java:84)at org.testng.TestNG.runSuitesSequentially(TestNG.java:1187)at org.testng.TestNG.runSuitesLocally(TestNG.java:1116)at org.testng.TestNG.runSuites(TestNG.java:1028)at org.testng.TestNG.run(TestNG.java:996)at org.testng.remote.AbstractRemoteTestNG.run(AbstractRemoteTestNG.java:114)at org.testng.remote.RemoteTestNG.initAndRun(RemoteTestNG.java:251)at org.testng.remote.RemoteTestNG.main(RemoteTestNG.java:77)]]>
    </failure>
  </testcase> <!-- userLogin -->
  <testcase name="userLogin" time="35.231" classname="DataDrivenFramework.DataDrivenLoginTest"/>
</testsuite> <!-- Default test -->
