<?xml version="1.0" encoding="UTF-8"?>
<testng-results skipped="0" failed="5" ignored="0" total="6" passed="1">
  <reporter-output>
  </reporter-output>
  <suite name="Default suite" duration-ms="220521" started-at="2017-12-24T08:55:26Z" finished-at="2017-12-24T08:59:07Z">
    <groups>
    </groups>
    <test name="Default test" duration-ms="220521" started-at="2017-12-24T08:55:26Z" finished-at="2017-12-24T08:59:07Z">
      <class name="DataDrivenFramework.DataDrivenLoginTest">
        <test-method status="FAIL" signature="userLogin(java.lang.String, java.lang.String, java.lang.String)[pri:0, instance:DataDrivenFramework.DataDrivenLoginTest@4493d195]" name="userLogin" duration-ms="49818" started-at="2017-12-24T11:55:27Z" data-provider="TestData" finished-at="2017-12-24T11:56:16Z">
          <params>
            <param index="0">
              <value>
                <![CDATA[Ja4oti@yahoo.com]]>
              </value>
            </param>
            <param index="1">
              <value>
                <![CDATA[banana]]>
              </value>
            </param>
            <param index="2">
              <value>
                <![CDATA[]]>
              </value>
            </param>
          </params>
          <exception class="java.lang.AssertionError">
            <message>
              <![CDATA[expected [My account - My Store] but found [Login - My Store]]]>
            </message>
            <full-stacktrace>
              <![CDATA[java.lang.AssertionError: expected [My account - My Store] but found [Login - My Store]at org.testng.Assert.fail(Assert.java:96)at org.testng.Assert.failNotEquals(Assert.java:776)at org.testng.Assert.assertEqualsImpl(Assert.java:137)at org.testng.Assert.assertEquals(Assert.java:118)at org.testng.Assert.assertEquals(Assert.java:453)at org.testng.Assert.assertEquals(Assert.java:463)at DataDrivenFramework.DataDrivenLoginTest.userLogin(DataDrivenLoginTest.java:33)at sun.reflect.NativeMethodAccessorImpl.invoke0(Native Method)at sun.reflect.NativeMethodAccessorImpl.invoke(Unknown Source)at sun.reflect.DelegatingMethodAccessorImpl.invoke(Unknown Source)at java.lang.reflect.Method.invoke(Unknown Source)at org.testng.internal.MethodInvocationHelper.invokeMethod(MethodInvocationHelper.java:124)at org.testng.internal.Invoker.invokeMethod(Invoker.java:571)at org.testng.internal.Invoker.invokeTestMethod(Invoker.java:707)at org.testng.internal.Invoker.invokeTestMethods(Invoker.java:979)at org.testng.internal.TestMethodWorker.invokeTestMethods(TestMethodWorker.java:125)at org.testng.internal.TestMethodWorker.run(TestMethodWorker.java:109)at org.testng.TestRunner.privateRun(TestRunner.java:648)at org.testng.TestRunner.run(TestRunner.java:505)at org.testng.SuiteRunner.runTest(SuiteRunner.java:455)at org.testng.SuiteRunner.runSequentially(SuiteRunner.java:450)at org.testng.SuiteRunner.privateRun(SuiteRunner.java:415)at org.testng.SuiteRunner.run(SuiteRunner.java:364)at org.testng.SuiteRunnerWorker.runSuite(SuiteRunnerWorker.java:52)at org.testng.SuiteRunnerWorker.run(SuiteRunnerWorker.java:84)at org.testng.TestNG.runSuitesSequentially(TestNG.java:1187)at org.testng.TestNG.runSuitesLocally(TestNG.java:1116)at org.testng.TestNG.runSuites(TestNG.java:1028)at org.testng.TestNG.run(TestNG.java:996)at org.testng.remote.AbstractRemoteTestNG.run(AbstractRemoteTestNG.java:114)at org.testng.remote.RemoteTestNG.initAndRun(RemoteTestNG.java:251)at org.testng.remote.RemoteTestNG.main(RemoteTestNG.java:77)]]>
            </full-stacktrace>
          </exception> <!-- java.lang.AssertionError -->
          <reporter-output>
          </reporter-output>
        </test-method> <!-- userLogin -->
        <test-method status="FAIL" signature="userLogin(java.lang.String, java.lang.String, java.lang.String)[pri:0, instance:DataDrivenFramework.DataDrivenLoginTest@4493d195]" name="userLogin" duration-ms="31845" started-at="2017-12-24T11:56:16Z" data-provider="TestData" finished-at="2017-12-24T11:56:48Z">
          <params>
            <param index="0">
              <value>
                <![CDATA[abc@gmail.com]]>
              </value>
            </param>
            <param index="1">
              <value>
                <![CDATA[avocado]]>
              </value>
            </param>
            <param index="2">
              <value>
                <![CDATA[]]>
              </value>
            </param>
          </params>
          <exception class="java.lang.AssertionError">
            <message>
              <![CDATA[expected [My account - My Store] but found [Login - My Store]]]>
            </message>
            <full-stacktrace>
              <![CDATA[java.lang.AssertionError: expected [My account - My Store] but found [Login - My Store]at org.testng.Assert.fail(Assert.java:96)at org.testng.Assert.failNotEquals(Assert.java:776)at org.testng.Assert.assertEqualsImpl(Assert.java:137)at org.testng.Assert.assertEquals(Assert.java:118)at org.testng.Assert.assertEquals(Assert.java:453)at org.testng.Assert.assertEquals(Assert.java:463)at DataDrivenFramework.DataDrivenLoginTest.userLogin(DataDrivenLoginTest.java:33)at sun.reflect.NativeMethodAccessorImpl.invoke0(Native Method)at sun.reflect.NativeMethodAccessorImpl.invoke(Unknown Source)at sun.reflect.DelegatingMethodAccessorImpl.invoke(Unknown Source)at java.lang.reflect.Method.invoke(Unknown Source)at org.testng.internal.MethodInvocationHelper.invokeMethod(MethodInvocationHelper.java:124)at org.testng.internal.Invoker.invokeMethod(Invoker.java:571)at org.testng.internal.Invoker.invokeTestMethod(Invoker.java:707)at org.testng.internal.Invoker.invokeTestMethods(Invoker.java:979)at org.testng.internal.TestMethodWorker.invokeTestMethods(TestMethodWorker.java:125)at org.testng.internal.TestMethodWorker.run(TestMethodWorker.java:109)at org.testng.TestRunner.privateRun(TestRunner.java:648)at org.testng.TestRunner.run(TestRunner.java:505)at org.testng.SuiteRunner.runTest(SuiteRunner.java:455)at org.testng.SuiteRunner.runSequentially(SuiteRunner.java:450)at org.testng.SuiteRunner.privateRun(SuiteRunner.java:415)at org.testng.SuiteRunner.run(SuiteRunner.java:364)at org.testng.SuiteRunnerWorker.runSuite(SuiteRunnerWorker.java:52)at org.testng.SuiteRunnerWorker.run(SuiteRunnerWorker.java:84)at org.testng.TestNG.runSuitesSequentially(TestNG.java:1187)at org.testng.TestNG.runSuitesLocally(TestNG.java:1116)at org.testng.TestNG.runSuites(TestNG.java:1028)at org.testng.TestNG.run(TestNG.java:996)at org.testng.remote.AbstractRemoteTestNG.run(AbstractRemoteTestNG.java:114)at org.testng.remote.RemoteTestNG.initAndRun(RemoteTestNG.java:251)at org.testng.remote.RemoteTestNG.main(RemoteTestNG.java:77)]]>
            </full-stacktrace>
          </exception> <!-- java.lang.AssertionError -->
          <reporter-output>
          </reporter-output>
        </test-method> <!-- userLogin -->
        <test-method status="FAIL" signature="userLogin(java.lang.String, java.lang.String, java.lang.String)[pri:0, instance:DataDrivenFramework.DataDrivenLoginTest@4493d195]" name="userLogin" duration-ms="29115" started-at="2017-12-24T11:56:48Z" data-provider="TestData" finished-at="2017-12-24T11:57:17Z">
          <params>
            <param index="0">
              <value>
                <![CDATA[1234@gmail.com]]>
              </value>
            </param>
            <param index="1">
              <value>
                <![CDATA[mangoes]]>
              </value>
            </param>
            <param index="2">
              <value>
                <![CDATA[]]>
              </value>
            </param>
          </params>
          <exception class="java.lang.AssertionError">
            <message>
              <![CDATA[expected [My account - My Store] but found [Login - My Store]]]>
            </message>
            <full-stacktrace>
              <![CDATA[java.lang.AssertionError: expected [My account - My Store] but found [Login - My Store]at org.testng.Assert.fail(Assert.java:96)at org.testng.Assert.failNotEquals(Assert.java:776)at org.testng.Assert.assertEqualsImpl(Assert.java:137)at org.testng.Assert.assertEquals(Assert.java:118)at org.testng.Assert.assertEquals(Assert.java:453)at org.testng.Assert.assertEquals(Assert.java:463)at DataDrivenFramework.DataDrivenLoginTest.userLogin(DataDrivenLoginTest.java:33)at sun.reflect.NativeMethodAccessorImpl.invoke0(Native Method)at sun.reflect.NativeMethodAccessorImpl.invoke(Unknown Source)at sun.reflect.DelegatingMethodAccessorImpl.invoke(Unknown Source)at java.lang.reflect.Method.invoke(Unknown Source)at org.testng.internal.MethodInvocationHelper.invokeMethod(MethodInvocationHelper.java:124)at org.testng.internal.Invoker.invokeMethod(Invoker.java:571)at org.testng.internal.Invoker.invokeTestMethod(Invoker.java:707)at org.testng.internal.Invoker.invokeTestMethods(Invoker.java:979)at org.testng.internal.TestMethodWorker.invokeTestMethods(TestMethodWorker.java:125)at org.testng.internal.TestMethodWorker.run(TestMethodWorker.java:109)at org.testng.TestRunner.privateRun(TestRunner.java:648)at org.testng.TestRunner.run(TestRunner.java:505)at org.testng.SuiteRunner.runTest(SuiteRunner.java:455)at org.testng.SuiteRunner.runSequentially(SuiteRunner.java:450)at org.testng.SuiteRunner.privateRun(SuiteRunner.java:415)at org.testng.SuiteRunner.run(SuiteRunner.java:364)at org.testng.SuiteRunnerWorker.runSuite(SuiteRunnerWorker.java:52)at org.testng.SuiteRunnerWorker.run(SuiteRunnerWorker.java:84)at org.testng.TestNG.runSuitesSequentially(TestNG.java:1187)at org.testng.TestNG.runSuitesLocally(TestNG.java:1116)at org.testng.TestNG.runSuites(TestNG.java:1028)at org.testng.TestNG.run(TestNG.java:996)at org.testng.remote.AbstractRemoteTestNG.run(AbstractRemoteTestNG.java:114)at org.testng.remote.RemoteTestNG.initAndRun(RemoteTestNG.java:251)at org.testng.remote.RemoteTestNG.main(RemoteTestNG.java:77)]]>
            </full-stacktrace>
          </exception> <!-- java.lang.AssertionError -->
          <reporter-output>
          </reporter-output>
        </test-method> <!-- userLogin -->
        <test-method status="FAIL" signature="userLogin(java.lang.String, java.lang.String, java.lang.String)[pri:0, instance:DataDrivenFramework.DataDrivenLoginTest@4493d195]" name="userLogin" duration-ms="45926" started-at="2017-12-24T11:57:17Z" data-provider="TestData" finished-at="2017-12-24T11:58:03Z">
          <params>
            <param index="0">
              <value>
                <![CDATA[trizzah@ymail.com]]>
              </value>
            </param>
            <param index="1">
              <value>
                <![CDATA[oranges]]>
              </value>
            </param>
            <param index="2">
              <value>
                <![CDATA[]]>
              </value>
            </param>
          </params>
          <exception class="java.lang.AssertionError">
            <message>
              <![CDATA[expected [My account - My Store] but found [Login - My Store]]]>
            </message>
            <full-stacktrace>
              <![CDATA[java.lang.AssertionError: expected [My account - My Store] but found [Login - My Store]at org.testng.Assert.fail(Assert.java:96)at org.testng.Assert.failNotEquals(Assert.java:776)at org.testng.Assert.assertEqualsImpl(Assert.java:137)at org.testng.Assert.assertEquals(Assert.java:118)at org.testng.Assert.assertEquals(Assert.java:453)at org.testng.Assert.assertEquals(Assert.java:463)at DataDrivenFramework.DataDrivenLoginTest.userLogin(DataDrivenLoginTest.java:33)at sun.reflect.NativeMethodAccessorImpl.invoke0(Native Method)at sun.reflect.NativeMethodAccessorImpl.invoke(Unknown Source)at sun.reflect.DelegatingMethodAccessorImpl.invoke(Unknown Source)at java.lang.reflect.Method.invoke(Unknown Source)at org.testng.internal.MethodInvocationHelper.invokeMethod(MethodInvocationHelper.java:124)at org.testng.internal.Invoker.invokeMethod(Invoker.java:571)at org.testng.internal.Invoker.invokeTestMethod(Invoker.java:707)at org.testng.internal.Invoker.invokeTestMethods(Invoker.java:979)at org.testng.internal.TestMethodWorker.invokeTestMethods(TestMethodWorker.java:125)at org.testng.internal.TestMethodWorker.run(TestMethodWorker.java:109)at org.testng.TestRunner.privateRun(TestRunner.java:648)at org.testng.TestRunner.run(TestRunner.java:505)at org.testng.SuiteRunner.runTest(SuiteRunner.java:455)at org.testng.SuiteRunner.runSequentially(SuiteRunner.java:450)at org.testng.SuiteRunner.privateRun(SuiteRunner.java:415)at org.testng.SuiteRunner.run(SuiteRunner.java:364)at org.testng.SuiteRunnerWorker.runSuite(SuiteRunnerWorker.java:52)at org.testng.SuiteRunnerWorker.run(SuiteRunnerWorker.java:84)at org.testng.TestNG.runSuitesSequentially(TestNG.java:1187)at org.testng.TestNG.runSuitesLocally(TestNG.java:1116)at org.testng.TestNG.runSuites(TestNG.java:1028)at org.testng.TestNG.run(TestNG.java:996)at org.testng.remote.AbstractRemoteTestNG.run(AbstractRemoteTestNG.java:114)at org.testng.remote.RemoteTestNG.initAndRun(RemoteTestNG.java:251)at org.testng.remote.RemoteTestNG.main(RemoteTestNG.java:77)]]>
            </full-stacktrace>
          </exception> <!-- java.lang.AssertionError -->
          <reporter-output>
          </reporter-output>
        </test-method> <!-- userLogin -->
        <test-method status="FAIL" signature="userLogin(java.lang.String, java.lang.String, java.lang.String)[pri:0, instance:DataDrivenFramework.DataDrivenLoginTest@4493d195]" name="userLogin" duration-ms="28258" started-at="2017-12-24T11:58:03Z" data-provider="TestData" finished-at="2017-12-24T11:58:32Z">
          <params>
            <param index="0">
              <value>
                <![CDATA[symo@hotmail.com]]>
              </value>
            </param>
            <param index="1">
              <value>
                <![CDATA[pineapple]]>
              </value>
            </param>
            <param index="2">
              <value>
                <![CDATA[]]>
              </value>
            </param>
          </params>
          <exception class="java.lang.AssertionError">
            <message>
              <![CDATA[expected [My account - My Store] but found [Login - My Store]]]>
            </message>
            <full-stacktrace>
              <![CDATA[java.lang.AssertionError: expected [My account - My Store] but found [Login - My Store]at org.testng.Assert.fail(Assert.java:96)at org.testng.Assert.failNotEquals(Assert.java:776)at org.testng.Assert.assertEqualsImpl(Assert.java:137)at org.testng.Assert.assertEquals(Assert.java:118)at org.testng.Assert.assertEquals(Assert.java:453)at org.testng.Assert.assertEquals(Assert.java:463)at DataDrivenFramework.DataDrivenLoginTest.userLogin(DataDrivenLoginTest.java:33)at sun.reflect.NativeMethodAccessorImpl.invoke0(Native Method)at sun.reflect.NativeMethodAccessorImpl.invoke(Unknown Source)at sun.reflect.DelegatingMethodAccessorImpl.invoke(Unknown Source)at java.lang.reflect.Method.invoke(Unknown Source)at org.testng.internal.MethodInvocationHelper.invokeMethod(MethodInvocationHelper.java:124)at org.testng.internal.Invoker.invokeMethod(Invoker.java:571)at org.testng.internal.Invoker.invokeTestMethod(Invoker.java:707)at org.testng.internal.Invoker.invokeTestMethods(Invoker.java:979)at org.testng.internal.TestMethodWorker.invokeTestMethods(TestMethodWorker.java:125)at org.testng.internal.TestMethodWorker.run(TestMethodWorker.java:109)at org.testng.TestRunner.privateRun(TestRunner.java:648)at org.testng.TestRunner.run(TestRunner.java:505)at org.testng.SuiteRunner.runTest(SuiteRunner.java:455)at org.testng.SuiteRunner.runSequentially(SuiteRunner.java:450)at org.testng.SuiteRunner.privateRun(SuiteRunner.java:415)at org.testng.SuiteRunner.run(SuiteRunner.java:364)at org.testng.SuiteRunnerWorker.runSuite(SuiteRunnerWorker.java:52)at org.testng.SuiteRunnerWorker.run(SuiteRunnerWorker.java:84)at org.testng.TestNG.runSuitesSequentially(TestNG.java:1187)at org.testng.TestNG.runSuitesLocally(TestNG.java:1116)at org.testng.TestNG.runSuites(TestNG.java:1028)at org.testng.TestNG.run(TestNG.java:996)at org.testng.remote.AbstractRemoteTestNG.run(AbstractRemoteTestNG.java:114)at org.testng.remote.RemoteTestNG.initAndRun(RemoteTestNG.java:251)at org.testng.remote.RemoteTestNG.main(RemoteTestNG.java:77)]]>
            </full-stacktrace>
          </exception> <!-- java.lang.AssertionError -->
          <reporter-output>
          </reporter-output>
        </test-method> <!-- userLogin -->
        <test-method status="PASS" signature="userLogin(java.lang.String, java.lang.String, java.lang.String)[pri:0, instance:DataDrivenFramework.DataDrivenLoginTest@4493d195]" name="userLogin" duration-ms="35231" started-at="2017-12-24T11:58:32Z" data-provider="TestData" finished-at="2017-12-24T11:59:07Z">
          <params>
            <param index="0">
              <value>
                <![CDATA[ja4oti@gmail.com]]>
              </value>
            </param>
            <param index="1">
              <value>
                <![CDATA[ja4macobudo]]>
              </value>
            </param>
            <param index="2">
              <value>
                <![CDATA[]]>
              </value>
            </param>
          </params>
          <reporter-output>
          </reporter-output>
        </test-method> <!-- userLogin -->
      </class> <!-- DataDrivenFramework.DataDrivenLoginTest -->
    </test> <!-- Default test -->
  </suite> <!-- Default suite -->
</testng-results>
